[2024-07-19T14:25:44.431+0000] {local_task_job_runner.py:120} INFO - ::group::Pre task execution logs
[2024-07-19T14:25:44.465+0000] {taskinstance.py:2076} INFO - Dependencies all met for dep_context=non-requeueable deps ti=<TaskInstance: csv_to_pgsql.extract_and_load_process manual__2024-07-19T14:25:37.517999+00:00 [queued]>
[2024-07-19T14:25:44.476+0000] {taskinstance.py:2076} INFO - Dependencies all met for dep_context=requeueable deps ti=<TaskInstance: csv_to_pgsql.extract_and_load_process manual__2024-07-19T14:25:37.517999+00:00 [queued]>
[2024-07-19T14:25:44.478+0000] {taskinstance.py:2306} INFO - Starting attempt 1 of 2
[2024-07-19T14:25:44.495+0000] {taskinstance.py:2330} INFO - Executing <Task(PythonOperator): extract_and_load_process> on 2024-07-19 14:25:37.517999+00:00
[2024-07-19T14:25:44.502+0000] {standard_task_runner.py:90} INFO - Running: ['***', 'tasks', 'run', 'csv_to_pgsql', 'extract_and_load_process', 'manual__2024-07-19T14:25:37.517999+00:00', '--job-id', '557', '--raw', '--subdir', 'DAGS_FOLDER/from_csv_to_pgsql.py', '--cfg-path', '/tmp/tmp5tq41p3j']
[2024-07-19T14:25:44.504+0000] {standard_task_runner.py:91} INFO - Job 557: Subtask extract_and_load_process
[2024-07-19T14:25:44.516+0000] {logging_mixin.py:188} WARNING - /home/***/.local/lib/python3.12/site-packages/***/task/task_runner/standard_task_runner.py:61 DeprecationWarning: This process (pid=4074) is multi-threaded, use of fork() may lead to deadlocks in the child.
[2024-07-19T14:25:44.518+0000] {standard_task_runner.py:63} INFO - Started process 4075 to run task
[2024-07-19T14:25:44.554+0000] {task_command.py:426} INFO - Running <TaskInstance: csv_to_pgsql.extract_and_load_process manual__2024-07-19T14:25:37.517999+00:00 [running]> on host 7c7e02e57379
[2024-07-19T14:25:44.653+0000] {taskinstance.py:2648} INFO - Exporting env vars: AIRFLOW_CTX_DAG_OWNER='***' AIRFLOW_CTX_DAG_ID='csv_to_pgsql' AIRFLOW_CTX_TASK_ID='extract_and_load_process' AIRFLOW_CTX_EXECUTION_DATE='2024-07-19T14:25:37.517999+00:00' AIRFLOW_CTX_TRY_NUMBER='1' AIRFLOW_CTX_DAG_RUN_ID='manual__2024-07-19T14:25:37.517999+00:00'
[2024-07-19T14:25:44.654+0000] {taskinstance.py:430} INFO - ::endgroup::
[2024-07-19T14:25:49.307+0000] {base.py:84} INFO - Using connection ID 'postgres_default' for task execution.
[2024-07-19T14:25:52.100+0000] {base.py:84} INFO - Using connection ID 'postgres_default' for task execution.
[2024-07-19T14:25:53.900+0000] {base.py:84} INFO - Using connection ID 'postgres_default' for task execution.
[2024-07-19T14:25:55.853+0000] {base.py:84} INFO - Using connection ID 'postgres_default' for task execution.
[2024-07-19T14:25:56.411+0000] {base.py:84} INFO - Using connection ID 'postgres_default' for task execution.
[2024-07-19T14:25:57.317+0000] {taskinstance.py:441} INFO - ::group::Post task execution logs
[2024-07-19T14:25:57.319+0000] {taskinstance.py:2905} ERROR - Task failed with exception
Traceback (most recent call last):
  File "/home/airflow/.local/lib/python3.12/site-packages/airflow/models/taskinstance.py", line 465, in _execute_task
    result = _execute_callable(context=context, **execute_callable_kwargs)
             ^^^^^^^^^^^^^^^^^^^^^^^^^^^^^^^^^^^^^^^^^^^^^^^^^^^^^^^^^^^^^
  File "/home/airflow/.local/lib/python3.12/site-packages/airflow/models/taskinstance.py", line 432, in _execute_callable
    return execute_callable(context=context, **execute_callable_kwargs)
           ^^^^^^^^^^^^^^^^^^^^^^^^^^^^^^^^^^^^^^^^^^^^^^^^^^^^^^^^^^^^
  File "/home/airflow/.local/lib/python3.12/site-packages/airflow/models/baseoperator.py", line 401, in wrapper
    return func(self, *args, **kwargs)
           ^^^^^^^^^^^^^^^^^^^^^^^^^^^
  File "/home/airflow/.local/lib/python3.12/site-packages/airflow/operators/python.py", line 235, in execute
    return_value = self.execute_callable()
                   ^^^^^^^^^^^^^^^^^^^^^^^
  File "/home/airflow/.local/lib/python3.12/site-packages/airflow/operators/python.py", line 252, in execute_callable
    return self.python_callable(*self.op_args, **self.op_kwargs)
           ^^^^^^^^^^^^^^^^^^^^^^^^^^^^^^^^^^^^^^^^^^^^^^^^^^^^^
  File "/opt/airflow/dags/from_csv_to_pgsql.py", line 110, in extract_and_load_task
    df = df.dropDuplicates(["data_actual_date", "currency_rk"])
         ^^^^^^^^^^^^^^^^^^^^^^^^^^^^^^^^^^^^^^^^^^^^^^^^^^^^^^
  File "/home/airflow/.local/lib/python3.12/site-packages/pyspark/sql/dataframe.py", line 4219, in dropDuplicates
    jdf = self._jdf.dropDuplicates(self._jseq(subset))
          ^^^^^^^^^^^^^^^^^^^^^^^^^^^^^^^^^^^^^^^^^^^^
  File "/home/airflow/.local/lib/python3.12/site-packages/py4j/java_gateway.py", line 1322, in __call__
    return_value = get_return_value(
                   ^^^^^^^^^^^^^^^^^
  File "/home/airflow/.local/lib/python3.12/site-packages/pyspark/errors/exceptions/captured.py", line 185, in deco
    raise converted from None
pyspark.errors.exceptions.captured.AnalysisException: Cannot resolve column name "data_actual_date" among (CHAPTER, CHAPTER_NAME, SECTION_NUMBER, SECTION_NAME, SUBSECTION_NAME, LEDGER1_ACCOUNT, LEDGER1_ACCOUNT_NAME, LEDGER_ACCOUNT, LEDGER_ACCOUNT_NAME, CHARACTERISTIC, START_DATE, END_DATE).
[2024-07-19T14:25:57.350+0000] {taskinstance.py:1206} INFO - Marking task as UP_FOR_RETRY. dag_id=csv_to_pgsql, task_id=extract_and_load_process, run_id=manual__2024-07-19T14:25:37.517999+00:00, execution_date=20240719T142537, start_date=20240719T142544, end_date=20240719T142557
[2024-07-19T14:25:57.362+0000] {standard_task_runner.py:110} ERROR - Failed to execute job 557 for task extract_and_load_process (Cannot resolve column name "data_actual_date" among (CHAPTER, CHAPTER_NAME, SECTION_NUMBER, SECTION_NAME, SUBSECTION_NAME, LEDGER1_ACCOUNT, LEDGER1_ACCOUNT_NAME, LEDGER_ACCOUNT, LEDGER_ACCOUNT_NAME, CHARACTERISTIC, START_DATE, END_DATE).; 4075)
[2024-07-19T14:25:57.383+0000] {local_task_job_runner.py:240} INFO - Task exited with return code 1
[2024-07-19T14:25:57.405+0000] {taskinstance.py:3503} INFO - 0 downstream tasks scheduled from follow-on schedule check
[2024-07-19T14:25:57.408+0000] {local_task_job_runner.py:222} INFO - ::endgroup::
