[2024-07-15T12:24:27.052+0000] {local_task_job_runner.py:120} INFO - ::group::Pre task execution logs
[2024-07-15T12:24:27.133+0000] {taskinstance.py:2076} INFO - Dependencies all met for dep_context=non-requeueable deps ti=<TaskInstance: csv_to_pgsql.start_process scheduled__2024-07-02T00:00:00+00:00 [queued]>
[2024-07-15T12:24:27.152+0000] {taskinstance.py:2076} INFO - Dependencies all met for dep_context=requeueable deps ti=<TaskInstance: csv_to_pgsql.start_process scheduled__2024-07-02T00:00:00+00:00 [queued]>
[2024-07-15T12:24:27.153+0000] {taskinstance.py:2306} INFO - Starting attempt 1 of 2
[2024-07-15T12:24:27.272+0000] {taskinstance.py:2330} INFO - Executing <Task(PythonOperator): start_process> on 2024-07-02 00:00:00+00:00
[2024-07-15T12:24:27.283+0000] {standard_task_runner.py:90} INFO - Running: ['***', 'tasks', 'run', 'csv_to_pgsql', 'start_process', 'scheduled__2024-07-02T00:00:00+00:00', '--job-id', '245', '--raw', '--subdir', 'DAGS_FOLDER/from_csv_to_pgsql.py', '--cfg-path', '/tmp/tmp4ea82rh0']
[2024-07-15T12:24:27.292+0000] {logging_mixin.py:188} WARNING - /home/***/.local/lib/python3.12/site-packages/***/task/task_runner/standard_task_runner.py:61 DeprecationWarning: This process (pid=365) is multi-threaded, use of fork() may lead to deadlocks in the child.
[2024-07-15T12:24:27.294+0000] {standard_task_runner.py:91} INFO - Job 245: Subtask start_process
[2024-07-15T12:24:27.296+0000] {standard_task_runner.py:63} INFO - Started process 372 to run task
[2024-07-15T12:24:27.692+0000] {task_command.py:426} INFO - Running <TaskInstance: csv_to_pgsql.start_process scheduled__2024-07-02T00:00:00+00:00 [running]> on host 1ee09c187a7a
[2024-07-15T12:24:28.146+0000] {taskinstance.py:2648} INFO - Exporting env vars: AIRFLOW_CTX_DAG_OWNER='***' AIRFLOW_CTX_DAG_ID='csv_to_pgsql' AIRFLOW_CTX_TASK_ID='start_process' AIRFLOW_CTX_EXECUTION_DATE='2024-07-02T00:00:00+00:00' AIRFLOW_CTX_TRY_NUMBER='1' AIRFLOW_CTX_DAG_RUN_ID='scheduled__2024-07-02T00:00:00+00:00'
[2024-07-15T12:24:28.151+0000] {taskinstance.py:430} INFO - ::endgroup::
[2024-07-15T12:24:28.236+0000] {taskinstance.py:441} INFO - ::group::Post task execution logs
[2024-07-15T12:24:28.276+0000] {taskinstance.py:2905} ERROR - Task failed with exception
Traceback (most recent call last):
  File "/home/airflow/.local/lib/python3.12/site-packages/airflow/models/taskinstance.py", line 465, in _execute_task
    result = _execute_callable(context=context, **execute_callable_kwargs)
             ^^^^^^^^^^^^^^^^^^^^^^^^^^^^^^^^^^^^^^^^^^^^^^^^^^^^^^^^^^^^^
  File "/home/airflow/.local/lib/python3.12/site-packages/airflow/models/taskinstance.py", line 432, in _execute_callable
    return execute_callable(context=context, **execute_callable_kwargs)
           ^^^^^^^^^^^^^^^^^^^^^^^^^^^^^^^^^^^^^^^^^^^^^^^^^^^^^^^^^^^^
  File "/home/airflow/.local/lib/python3.12/site-packages/airflow/models/baseoperator.py", line 401, in wrapper
    return func(self, *args, **kwargs)
           ^^^^^^^^^^^^^^^^^^^^^^^^^^^
  File "/home/airflow/.local/lib/python3.12/site-packages/airflow/operators/python.py", line 235, in execute
    return_value = self.execute_callable()
                   ^^^^^^^^^^^^^^^^^^^^^^^
  File "/home/airflow/.local/lib/python3.12/site-packages/airflow/operators/python.py", line 252, in execute_callable
    return self.python_callable(*self.op_args, **self.op_kwargs)
           ^^^^^^^^^^^^^^^^^^^^^^^^^^^^^^^^^^^^^^^^^^^^^^^^^^^^^
  File "/opt/airflow/dags/from_csv_to_pgsql.py", line 26, in start_process
    connection = hook.get_conn()
                 ^^^^^^^^^^^^^^^
  File "/home/airflow/.local/lib/python3.12/site-packages/airflow/providers/postgres/hooks/postgres.py", line 145, in get_conn
    conn = deepcopy(self.connection or self.get_connection(conn_id))
                                       ^^^^^^^^^^^^^^^^^^^^^^^^^^^^
  File "/home/airflow/.local/lib/python3.12/site-packages/airflow/hooks/base.py", line 83, in get_connection
    conn = Connection.get_connection_from_secrets(conn_id)
           ^^^^^^^^^^^^^^^^^^^^^^^^^^^^^^^^^^^^^^^^^^^^^^^
  File "/home/airflow/.local/lib/python3.12/site-packages/airflow/models/connection.py", line 519, in get_connection_from_secrets
    raise AirflowNotFoundException(f"The conn_id `{conn_id}` isn't defined")
airflow.exceptions.AirflowNotFoundException: The conn_id `postgres_defaul` isn't defined
[2024-07-15T12:24:28.318+0000] {taskinstance.py:1206} INFO - Marking task as UP_FOR_RETRY. dag_id=csv_to_pgsql, task_id=start_process, run_id=scheduled__2024-07-02T00:00:00+00:00, execution_date=20240702T000000, start_date=20240715T122427, end_date=20240715T122428
[2024-07-15T12:24:28.357+0000] {standard_task_runner.py:110} ERROR - Failed to execute job 245 for task start_process (The conn_id `postgres_defaul` isn't defined; 372)
[2024-07-15T12:24:28.401+0000] {local_task_job_runner.py:240} INFO - Task exited with return code 1
[2024-07-15T12:24:28.431+0000] {local_task_job_runner.py:222} INFO - ::endgroup::
