[2024-07-19T20:48:57.601+0000] {local_task_job_runner.py:120} INFO - ::group::Pre task execution logs
[2024-07-19T20:48:57.629+0000] {taskinstance.py:2076} INFO - Dependencies all met for dep_context=non-requeueable deps ti=<TaskInstance: load.save_to_pg manual__2024-07-19T20:43:48.079037+00:00 [queued]>
[2024-07-19T20:48:57.638+0000] {taskinstance.py:2076} INFO - Dependencies all met for dep_context=requeueable deps ti=<TaskInstance: load.save_to_pg manual__2024-07-19T20:43:48.079037+00:00 [queued]>
[2024-07-19T20:48:57.638+0000] {taskinstance.py:2306} INFO - Starting attempt 2 of 2
[2024-07-19T20:48:57.651+0000] {taskinstance.py:2330} INFO - Executing <Task(PythonOperator): save_to_pg> on 2024-07-19 20:43:48.079037+00:00
[2024-07-19T20:48:57.657+0000] {standard_task_runner.py:90} INFO - Running: ['***', 'tasks', 'run', 'load', 'save_to_pg', 'manual__2024-07-19T20:43:48.079037+00:00', '--job-id', '687', '--raw', '--subdir', 'DAGS_FOLDER/load.py', '--cfg-path', '/tmp/tmp6o1kfaeb']
[2024-07-19T20:48:57.659+0000] {standard_task_runner.py:91} INFO - Job 687: Subtask save_to_pg
[2024-07-19T20:48:57.659+0000] {logging_mixin.py:188} WARNING - /home/***/.local/lib/python3.12/site-packages/***/task/task_runner/standard_task_runner.py:61 DeprecationWarning: This process (pid=5257) is multi-threaded, use of fork() may lead to deadlocks in the child.
[2024-07-19T20:48:57.660+0000] {standard_task_runner.py:63} INFO - Started process 5258 to run task
[2024-07-19T20:48:57.699+0000] {task_command.py:426} INFO - Running <TaskInstance: load.save_to_pg manual__2024-07-19T20:43:48.079037+00:00 [running]> on host 7c7e02e57379
[2024-07-19T20:48:57.771+0000] {taskinstance.py:2648} INFO - Exporting env vars: AIRFLOW_CTX_DAG_OWNER='***' AIRFLOW_CTX_DAG_ID='load' AIRFLOW_CTX_TASK_ID='save_to_pg' AIRFLOW_CTX_EXECUTION_DATE='2024-07-19T20:43:48.079037+00:00' AIRFLOW_CTX_TRY_NUMBER='2' AIRFLOW_CTX_DAG_RUN_ID='manual__2024-07-19T20:43:48.079037+00:00'
[2024-07-19T20:48:57.772+0000] {taskinstance.py:430} INFO - ::endgroup::
[2024-07-19T20:49:01.397+0000] {taskinstance.py:441} INFO - ::group::Post task execution logs
[2024-07-19T20:49:01.398+0000] {taskinstance.py:2905} ERROR - Task failed with exception
Traceback (most recent call last):
  File "/home/airflow/.local/lib/python3.12/site-packages/airflow/models/taskinstance.py", line 465, in _execute_task
    result = _execute_callable(context=context, **execute_callable_kwargs)
             ^^^^^^^^^^^^^^^^^^^^^^^^^^^^^^^^^^^^^^^^^^^^^^^^^^^^^^^^^^^^^
  File "/home/airflow/.local/lib/python3.12/site-packages/airflow/models/taskinstance.py", line 432, in _execute_callable
    return execute_callable(context=context, **execute_callable_kwargs)
           ^^^^^^^^^^^^^^^^^^^^^^^^^^^^^^^^^^^^^^^^^^^^^^^^^^^^^^^^^^^^
  File "/home/airflow/.local/lib/python3.12/site-packages/airflow/models/baseoperator.py", line 401, in wrapper
    return func(self, *args, **kwargs)
           ^^^^^^^^^^^^^^^^^^^^^^^^^^^
  File "/home/airflow/.local/lib/python3.12/site-packages/airflow/operators/python.py", line 235, in execute
    return_value = self.execute_callable()
                   ^^^^^^^^^^^^^^^^^^^^^^^
  File "/home/airflow/.local/lib/python3.12/site-packages/airflow/operators/python.py", line 252, in execute_callable
    return self.python_callable(*self.op_args, **self.op_kwargs)
           ^^^^^^^^^^^^^^^^^^^^^^^^^^^^^^^^^^^^^^^^^^^^^^^^^^^^^
  File "/opt/airflow/dags/load.py", line 50, in extract_from_csv_to_pg
    df = spark.read.csv(f'/opt/airflow/files/dm_f101_round_f.csv/part-00000-daf24d17-1bbd-401a-a88a-d4a549303db0-c000.csv', sep=',', header=True, schema=schema)
         ^^^^^^^^^^^^^^^^^^^^^^^^^^^^^^^^^^^^^^^^^^^^^^^^^^^^^^^^^^^^^^^^^^^^^^^^^^^^^^^^^^^^^^^^^^^^^^^^^^^^^^^^^^^^^^^^^^^^^^^^^^^^^^^^^^^^^^^^^^^^^^^^^^^^^^^
  File "/home/airflow/.local/lib/python3.12/site-packages/pyspark/sql/readwriter.py", line 740, in csv
    return self._df(self._jreader.csv(self._spark._sc._jvm.PythonUtils.toSeq(path)))
                    ^^^^^^^^^^^^^^^^^^^^^^^^^^^^^^^^^^^^^^^^^^^^^^^^^^^^^^^^^^^^^^^
  File "/home/airflow/.local/lib/python3.12/site-packages/py4j/java_gateway.py", line 1322, in __call__
    return_value = get_return_value(
                   ^^^^^^^^^^^^^^^^^
  File "/home/airflow/.local/lib/python3.12/site-packages/pyspark/errors/exceptions/captured.py", line 185, in deco
    raise converted from None
pyspark.errors.exceptions.captured.AnalysisException: [PATH_NOT_FOUND] Path does not exist: file:/opt/airflow/files/dm_f101_round_f.csv/part-00000-daf24d17-1bbd-401a-a88a-d4a549303db0-c000.csv.
[2024-07-19T20:49:01.423+0000] {taskinstance.py:1206} INFO - Marking task as FAILED. dag_id=load, task_id=save_to_pg, run_id=manual__2024-07-19T20:43:48.079037+00:00, execution_date=20240719T204348, start_date=20240719T204857, end_date=20240719T204901
[2024-07-19T20:49:01.435+0000] {standard_task_runner.py:110} ERROR - Failed to execute job 687 for task save_to_pg ([PATH_NOT_FOUND] Path does not exist: file:/opt/airflow/files/dm_f101_round_f.csv/part-00000-daf24d17-1bbd-401a-a88a-d4a549303db0-c000.csv.; 5258)
[2024-07-19T20:49:01.454+0000] {local_task_job_runner.py:240} INFO - Task exited with return code 1
[2024-07-19T20:49:01.470+0000] {taskinstance.py:3503} INFO - 0 downstream tasks scheduled from follow-on schedule check
[2024-07-19T20:49:01.473+0000] {local_task_job_runner.py:222} INFO - ::endgroup::
