[2024-07-18T15:52:49.549+0000] {local_task_job_runner.py:120} INFO - ::group::Pre task execution logs
[2024-07-18T15:52:49.573+0000] {taskinstance.py:2076} INFO - Dependencies all met for dep_context=non-requeueable deps ti=<TaskInstance: run_fill_procedure.fill_dm_account_turnover manual__2024-07-18T15:52:32.333326+00:00 [queued]>
[2024-07-18T15:52:49.580+0000] {taskinstance.py:2076} INFO - Dependencies all met for dep_context=requeueable deps ti=<TaskInstance: run_fill_procedure.fill_dm_account_turnover manual__2024-07-18T15:52:32.333326+00:00 [queued]>
[2024-07-18T15:52:49.581+0000] {taskinstance.py:2306} INFO - Starting attempt 1 of 2
[2024-07-18T15:52:49.591+0000] {taskinstance.py:2330} INFO - Executing <Task(PythonOperator): fill_dm_account_turnover> on 2024-07-18 15:52:32.333326+00:00
[2024-07-18T15:52:49.602+0000] {standard_task_runner.py:90} INFO - Running: ['***', 'tasks', 'run', 'run_fill_procedure', 'fill_dm_account_turnover', 'manual__2024-07-18T15:52:32.333326+00:00', '--job-id', '443', '--raw', '--subdir', 'DAGS_FOLDER/create_and_fill_proc.py', '--cfg-path', '/tmp/tmpx34miy3y']
[2024-07-18T15:52:49.604+0000] {standard_task_runner.py:91} INFO - Job 443: Subtask fill_dm_account_turnover
[2024-07-18T15:52:49.607+0000] {logging_mixin.py:188} WARNING - /home/***/.local/lib/python3.12/site-packages/***/task/task_runner/standard_task_runner.py:61 DeprecationWarning: This process (pid=6069) is multi-threaded, use of fork() may lead to deadlocks in the child.
[2024-07-18T15:52:49.608+0000] {standard_task_runner.py:63} INFO - Started process 6070 to run task
[2024-07-18T15:52:49.640+0000] {task_command.py:426} INFO - Running <TaskInstance: run_fill_procedure.fill_dm_account_turnover manual__2024-07-18T15:52:32.333326+00:00 [running]> on host 7c7e02e57379
[2024-07-18T15:52:49.704+0000] {taskinstance.py:2648} INFO - Exporting env vars: AIRFLOW_CTX_DAG_OWNER='***' AIRFLOW_CTX_DAG_ID='run_fill_procedure' AIRFLOW_CTX_TASK_ID='fill_dm_account_turnover' AIRFLOW_CTX_EXECUTION_DATE='2024-07-18T15:52:32.333326+00:00' AIRFLOW_CTX_TRY_NUMBER='1' AIRFLOW_CTX_DAG_RUN_ID='manual__2024-07-18T15:52:32.333326+00:00'
[2024-07-18T15:52:49.706+0000] {taskinstance.py:430} INFO - ::endgroup::
[2024-07-18T15:52:49.721+0000] {base.py:84} INFO - Using connection ID 'postgres_default' for task execution.
[2024-07-18T15:52:49.734+0000] {taskinstance.py:441} INFO - ::group::Post task execution logs
[2024-07-18T15:52:49.735+0000] {taskinstance.py:2905} ERROR - Task failed with exception
Traceback (most recent call last):
  File "/home/airflow/.local/lib/python3.12/site-packages/airflow/models/taskinstance.py", line 465, in _execute_task
    result = _execute_callable(context=context, **execute_callable_kwargs)
             ^^^^^^^^^^^^^^^^^^^^^^^^^^^^^^^^^^^^^^^^^^^^^^^^^^^^^^^^^^^^^
  File "/home/airflow/.local/lib/python3.12/site-packages/airflow/models/taskinstance.py", line 432, in _execute_callable
    return execute_callable(context=context, **execute_callable_kwargs)
           ^^^^^^^^^^^^^^^^^^^^^^^^^^^^^^^^^^^^^^^^^^^^^^^^^^^^^^^^^^^^
  File "/home/airflow/.local/lib/python3.12/site-packages/airflow/models/baseoperator.py", line 401, in wrapper
    return func(self, *args, **kwargs)
           ^^^^^^^^^^^^^^^^^^^^^^^^^^^
  File "/home/airflow/.local/lib/python3.12/site-packages/airflow/operators/python.py", line 235, in execute
    return_value = self.execute_callable()
                   ^^^^^^^^^^^^^^^^^^^^^^^
  File "/home/airflow/.local/lib/python3.12/site-packages/airflow/operators/python.py", line 252, in execute_callable
    return self.python_callable(*self.op_args, **self.op_kwargs)
           ^^^^^^^^^^^^^^^^^^^^^^^^^^^^^^^^^^^^^^^^^^^^^^^^^^^^^
  File "/opt/airflow/dags/create_and_fill_proc.py", line 144, in fill_dm_account_turnover
    cursor.execute(sql)
psycopg2.errors.UndefinedColumn: column "credit_amount_rk" does not exist
LINE 11:  credit_amount_rk as account_rk,
          ^
HINT:  Perhaps you meant to reference the column "ft_posting_f.credit_account_rk" or the column "dm_account_turnover_f.credit_amount_rub".
QUERY:  insert into dm.dm_account_turnover_f (on_date, account_rk, credit_amount, credit_amount_rub, debet_amount, debet_amount_rub)
select 
	i_OnDate as on_date,
	account_rk,
	sum(credit_amount) as credit_amount,
	sum(credit_amount * coalesce(er.reduced_cource, 1)) as credit_amount_rub,
	sum(debet_amount) as debet_amount,
	sum(debet_amount * coalesce(er.reduced_cource, 1)) as debet_amount_rub
	from(
select 
	credit_amount_rk as account_rk,
	credit_amount,
	0 as debet_amount
from ds.ft_posting_f
where oper_date = i_OnDate
UNION ALL
select
	debet_account_rk as account_rk,
	0 as credit_amount,
	debet_amount
from ds.ft_posting_f
where oper_date = i_OnDate
	) as turnover
left join ds.md_exchange_rate_d er
on er.data_actual_date = i_OnDate
group by account_rk
CONTEXT:  PL/pgSQL function dm.fill_account_turnover_f(date) line 5 at SQL statement
SQL statement "CALL dm.fill_account_turnover_f(d)"
PL/pgSQL function inline_code_block line 12 at CALL

[2024-07-18T15:52:49.746+0000] {taskinstance.py:1206} INFO - Marking task as UP_FOR_RETRY. dag_id=run_fill_procedure, task_id=fill_dm_account_turnover, run_id=manual__2024-07-18T15:52:32.333326+00:00, execution_date=20240718T155232, start_date=20240718T155249, end_date=20240718T155249
[2024-07-18T15:52:49.759+0000] {standard_task_runner.py:110} ERROR - Failed to execute job 443 for task fill_dm_account_turnover (column "credit_amount_rk" does not exist
LINE 11:  credit_amount_rk as account_rk,
          ^
HINT:  Perhaps you meant to reference the column "ft_posting_f.credit_account_rk" or the column "dm_account_turnover_f.credit_amount_rub".
QUERY:  insert into dm.dm_account_turnover_f (on_date, account_rk, credit_amount, credit_amount_rub, debet_amount, debet_amount_rub)
select 
	i_OnDate as on_date,
	account_rk,
	sum(credit_amount) as credit_amount,
	sum(credit_amount * coalesce(er.reduced_cource, 1)) as credit_amount_rub,
	sum(debet_amount) as debet_amount,
	sum(debet_amount * coalesce(er.reduced_cource, 1)) as debet_amount_rub
	from(
select 
	credit_amount_rk as account_rk,
	credit_amount,
	0 as debet_amount
from ds.ft_posting_f
where oper_date = i_OnDate
UNION ALL
select
	debet_account_rk as account_rk,
	0 as credit_amount,
	debet_amount
from ds.ft_posting_f
where oper_date = i_OnDate
	) as turnover
left join ds.md_exchange_rate_d er
on er.data_actual_date = i_OnDate
group by account_rk
CONTEXT:  PL/pgSQL function dm.fill_account_turnover_f(date) line 5 at SQL statement
SQL statement "CALL dm.fill_account_turnover_f(d)"
PL/pgSQL function inline_code_block line 12 at CALL
; 6070)
[2024-07-18T15:52:49.792+0000] {local_task_job_runner.py:240} INFO - Task exited with return code 1
[2024-07-18T15:52:49.803+0000] {logging_mixin.py:188} WARNING - /home/***/.local/lib/python3.12/site-packages/***/models/baseoperator.py:1297 AirflowProviderDeprecationWarning: Call to deprecated class PostgresOperator. (Please use `***.providers.common.sql.operators.sql.SQLExecuteQueryOperator`.Also, you can provide `hook_params={'schema': <database>}`.)
[2024-07-18T15:52:49.814+0000] {taskinstance.py:3503} INFO - 0 downstream tasks scheduled from follow-on schedule check
[2024-07-18T15:52:49.816+0000] {local_task_job_runner.py:222} INFO - ::endgroup::
